Workbook

Sheet Appendix-A
D1: APPENDIX-A
D2: CONSUMER PRICES OF ESSENTIAL ITEMS
A3: SL. | D3: Islamabad (01) | G3: Rawalpindi (02) | J3: Gujranwala (03) | M3: Sialkot (04) | P3: Lahore (05) | S3: Faisalabad (06) | V3: Sargodha (07) | Y3: SL.
A4: NO. | B4: DESCRIPTION | C4: UNIT | D4: MIN | E4: AVG | F4: MAX | G4: MIN | H4: AVG | I4: MAX | J4: MIN | K4: AVG | L4: MAX | M4: MIN | N4: AVG | O4: MAX | P4: MIN | Q4: AVG | R4: MAX | S4: MIN | T4: AVG | U4: MAX | V4: MIN | W4: AVG | X4: MAX | Y4: NO.
A5: 1 | B5: 2 | C5: 3 | D5: 4 | E5: 5 | F5: 6 | G5: 7 | H5: 8 | I5: 9 | J5: 10 | K5: 11 | L5: 12 | M5: 13 | N5: 14 | O5: 15 | P5: 16 | Q5: 17 | R5: 18 | S5: 19 | T5: 20 | U5: 21 | V5: 22 | W5: 23 | X5: 24 | Y5: 1
D6: PRICES ON 23-07-2026
A7: 1 | B7: Wheat Flour Bag | C7: 20 Kg | D7: 2880 | E7: 2919.93 | F7: 2960 | G7: 2200 | H7: 2684.48 | I7: 2933.33 | J7: 2200 | K7: 2501.25 | L7: 2667 | M7: 2200 | N7: 2459.18 | O7: 2600 | P7: 2250 | Q7: 2266.54 | R7: 2300 | S7: 2200 | T7: 2395.71 | U7: 2500 | V7: 2200 | W7: 2325.98 | X7: 2600 | Y7: 1
A8: 2 | B8: Rice Basmati Broken (Average Quality) | C8: 1 Kg | D8: 260 | E8: 274.83 | F8: 290 | G8: 260 | H8: 270.58 | I8: 280 | J8: 180 | K8: 180 | L8: 180 | M8: 190 | N8: 190 | O8: 190 | P8: 220 | Q8: 228.47 | R8: 240 | S8: 220 | T8: 233.14 | U8: 240 | V8: 150 | W8: 156.59 | X8: 160 | Y8: 2
A9: 3 | B9: Rice IRRI-6/9 (Sindh/Punjab) | C9: 1 Kg | D9: 160 | E9: 178.64 | F9: 200 | G9: 150 | H9: 164.27 | I9: 180 | J9: 0 | K9: 0 | L9: 0 | M9: 0 | N9: 0 | O9: 0 | P9: 0 | Q9: 0 | R9: 0 | S9: 160 | T9: 160 | U9: 160 | V9: 180 | W9: 186.61 | X9: 190 | Y9: 3
A10: 4 | B10: Bread plain (Small Size) | C10: Each | D10: 120 | E10: 120 | F10: 120 | G10: 120 | H10: 120 | I10: 120 | J10: 120 | K10: 120 | L10: 120 | M10: 130 | N10: 130 | O10: 130 | P10: 130 | Q10: 130 | R10: 130 | S10: 120 | T10: 120 | U10: 120 | V10: 100 | W10: 100 | X10: 100 | Y10: 4
A11: 5 | B11: Beef with Bone (Average Quality) | C11: 1 Kg | D11: 1450 | E11: 1487.07 | F11: 1550 | G11: 1450 | H11: 1486.28 | I11: 1550 | J11: 1200 | K11: 1200 | L11: 1200 | M11: 1300 | N11: 1300 | O11: 1300 | P11: 1100 | Q11: 1231.32 | R11: 1300 | S11: 1200 | T11: 1329.88 | U11: 1400 | V11: 1150 | W11: 1166.43 | X11: 1200 | Y11: 5
A12: 6 | B12: Mutton (Average Quality) | C12: 1 Kg | D12: 2800 | E12: 2837.27 | F12: 2900 | G12: 2700 | H12: 2786.4 | I12: 2850 | J12: 2600 | K12: 2600 | L12: 2600 | M12: 2500 | N12: 2500 | O12: 2500 | P12: 2900 | Q12: 2928.23 | R12: 3000 | S12: 2200 | T12: 2331.39 | U12: 2400 | V12: 2150 | W12: 2183.21 | X12: 2200 | Y12: 6
A13: 7 | B13: Chicken Farm Broiler (Live) | C13: 1 Kg | D13: 375 | E13: 388.11 | F13: 410 | G13: 390 | H13: 397.28 | I13: 410 | J13: 358 | K13: 358 | L13: 358 | M13: 358 | N13: 358 | O13: 358 | P13: 353 | Q13: 353 | R13: 353 | S13: 390 | T13: 390 | U13: 390 | V13: 380 | W13: 383.3 | X13: 390 | Y13: 7
A14: 8 | B14: Milk fresh (Un-boiled) | C14: 1 Ltr | D14: 240 | E14: 249.88 | F14: 260 | G14: 220 | H14: 240.97 | I14: 260 | J14: 220 | K14: 220 | L14: 220 | M14: 180 | N14: 211.95 | O14: 230 | P14: 200 | Q14: 212.32 | R14: 220 | S14: 200 | T14: 206.46 | U14: 220 | V14: 170 | W14: 176.6 | X14: 180 | Y14: 8
A15: 9 | B15: Curd (Dahi) Loose | C15: 1 Kg | D15: 260 | E15: 272.37 | F15: 280 | G15: 240 | H15: 266.4 | I15: 280 | J15: 240 | K15: 240 | L15: 240 | M15: 190 | N15: 218.89 | O15: 240 | P15: 240 | Q15: 252.8 | R15: 260 | S15: 240 | T15: 240 | U15: 240 | V15: 220 | W15: 223.28 | X15: 230 | Y15: 9
A16: 10 | B16: Powdered Milk NIDO 390 gm Polybag | C16: Each | D16: 1160 | E16: 1180.77 | F16: 1200 | G16: 1160 | H16: 1176.63 | I16: 1200 | J16: 1160 | K16: 1163.32 | L16: 1170 | M16: 1200 | N16: 1200 | O16: 1200 | P16: 1170 | Q16: 1170 | R16: 1170 | S16: 1170 | T16: 1170 | U16: 1170 | V16: 1150 | W16: 1153.32 | X16: 1160 | Y16: 10
A17: 11 | B17: Eggs Hen (Farm) | C17: 1 Dozen | D17: 258 | E17: 265.17 | F17: 280 | G17: 258 | H17: 264.46 | I17: 280 | J17: 270 | K17: 270 | L17: 270 | M17: 270 | N17: 270 | O17: 270 | P17: 257 | Q17: 257 | R17: 257 | S17: 257 | T17: 257 | U17: 257 | V17: 257 | W17: 257 | X17: 257 | Y17: 11
A18: 12 | B18: Mustard Oil (Average Quality) | C18: 1 Kg | D18: 660 | E18: 686.46 | F18: 720 | G18: 650 | H18: 659.3 | I18: 670 | J18: 500 | K18: 500 | L18: 500 | M18: 550 | N18: 550 | O18: 550 | P18: 540 | Q18: 556.61 | R18: 570 | S18: 560 | T18: 560 | U18: 560 | V18: 480 | W18: 493.24 | X18: 500 | Y18: 12
... A57: 51 | B57: Toilet Soap LIFEBUOY 115 gm | C57: Each | D57: 117.34 | E57: 117.34 | F57: 117.34 | G57: 117.34 | H57: 117.34 | I57: 117.34 | J57: 117.34 | K57: 117.34 | L57: 117.34 | M57: 117 | N57: 117 | O57: 117 | P57: 116.17 | Q57: 116.17 | R57: 116.17 | S57: 116.17 | T57: 116.17 | U57: 116.17 | V57: 117.34 | W57: 117.34 | X57: 117.34 | Y57: 51
D59: APPENDIX-A
D60: CONSUMER PRICES OF ESSENTIAL ITEMS
A61: SL. | D61: Multan (08) | G61: Bahawalpur (09) | J61: Karachi (10) | M61: Hyderabad (11) | P61: Sukkur (12) | S61: Larkana (13) | V61: Peshawar (14) | Y61: SL.
A62: NO. | B62: DESCRIPTION | C62: UNIT | D62: MIN | E62: AVG | F62: MAX | G62: MIN | H62: AVG | I62: MAX | J62: MIN | K62: AVG | L62: MAX | M62: MIN | N62: AVG | O62: MAX | P62: MIN | Q62: AVG | R62: MAX | S62: MIN | T62: AVG | U62: MAX | V62: MIN | W62: AVG | X62: MAX | Y62: NO.
A63: 1 | B63: 2 | C63: 3 | D63: 25 | E63: 26 | F63: 27 | G63: 28 | H63: 29 | I63: 30 | J63: 31 | K63: 32 | L63: 33 | M63: 34 | N63: 35 | O63: 36 | P63: 37 | Q63: 38 | R63: 39 | S63: 40 | T63: 41 | U63: 42 | V63: 43 | W63: 44 | X63: 45 | Y63: 1
D64: PRICES ON 23-07-2026
A65: 1 | B65: Wheat Flour Bag | C65: 20 Kg | D65: 2200 | E65: 2312.25 | F65: 2666.66 | G65: 2680 | H65: 2693.27 | I65: 2720 | J65: 2600 | K65: 2729.47 | L65: 2900 | M65: 2720 | N65: 2754.95 | O65: 2780 | P65: 2500 | Q65: 2500 | R65: 2500 | S65: 2500 | T65: 2500 | U65: 2500 | V65: 2800 | W65: 2888.52 | X65: 2950 | Y65: 1
A66: 2 | B66: Rice Basmati Broken (Average Quality) | C66: 1 Kg | D66: 180 | E66: 193.1 | F66: 200 | G66: 190 | H66: 203.11 | I66: 210 | J66: 260 | K66: 279.31 | L66: 290 | M66: 200 | N66: 213.12 | O66: 220 | P66: 200 | Q66: 200 | R66: 200 | S66: 230 | T66: 236.62 | U66: 240 | V66: 220 | W66: 222.18 | X66: 230 | Y66: 2
A67: 3 | B67: Rice IRRI-6/9 (Sindh/Punjab) | C67: 1 Kg | D67: 130 | E67: 140.92 | F67: 150 | G67: 190 | H67: 196.61 | I67: 200 | J67: 160 | K67: 173.88 | L67: 190 | M67: 120 | N67: 123.24 | O67: 130 | P67: 130 | Q67: 130 | R67: 130 | S67: 110 | T67: 116.57 | U67: 120 | V67: 130 | W67: 130 | X67: 130 | Y67: 3
A68: 4 | B68: Bread plain (Small Size) | C68: Each | D68: 120 | E68: 120 | F68: 120 | G68: 110 | H68: 110 | I68: 110 | J68: 130 | K68: 130 | L68: 130 | M68: 130 | N68: 130 | O68: 130 | P68: 130 | Q68: 130 | R68: 130 | S68: 110 | T68: 116.57 | U68: 120 | V68: 120 | W68: 120 | X68: 120 | Y68: 4
A69: 5 | B69: Beef with Bone (Average Quality) | C69: 1 Kg | D69: 1250 | E69: 1299.79 | F69: 1350 | G69: 1100 | H69: 1116.42 | I69: 1150 | J69: 1400 | K69: 1437.1 | L69: 1500 | M69: 1200 | N69: 1245.26 | O69: 1300 | P69: 1200 | Q69: 1200 | R69: 1200 | S69: 1200 | T69: 1232.45 | U69: 1300 | V69: 1100 | W69: 1257.63 | X69: 1400 | Y69: 5
A70: 6 | B70: Mutton (Average Quality) | C70: 1 Kg | D70: 2300 | E70: 2404.92 | F70: 2500 | G70: 2200 | H70: 2266.17 | I70: 2300 | J70: 2200 | K70: 2447.57 | L70: 2800 | M70: 2350 | N70: 2395.62 | O70: 2450 | P70: 2000 | Q70: 2000 | R70: 2000 | S70: 2000 | T70: 2131.2 | U70: 2200 | V70: 2100 | W70: 2283.33 | X70: 2500 | Y70: 6
A71: 7 | B71: Chicken Farm Broiler (Live) | C71: 1 Kg | D71: 355 | E71: 355 | F71: 355 | G71: 320 | H71: 320 | I71: 320 | J71: 320 | K71: 336.23 | L71: 350 | M71: 310 | N71: 314.96 | O71: 320 | P71: 340 | Q71: 340 | R71: 340 | S71: 330 | T71: 330 | U71: 330 | V71: 395 | W71: 395 | X71: 395 | Y71: 7
A72: 8 | B72: Milk fresh (Un-boiled) | C72: 1 Ltr | D72: 200 | E72: 205.5 | F72: 210 | G72: 180 | H72: 180 | I72: 180 | J72: 240 | K72: 240 | L72: 240 | M72: 230 | N72: 230 | O72: 230 | P72: 200 | Q72: 200 | R72: 200 | S72: 240 | T72: 243.29 | U72: 250 | V72: 240 | W72: 262.06 | X72: 270 | Y72: 8
A73: 9 | B73: Curd (Dahi) Loose | C73: 1 Kg | D73: 250 | E73: 253.29 | F73: 260 | G73: 220 | H73: 220 | I73: 220 | J73: 360 | K73: 364.06 | L73: 400 | M73: 320 | N73: 324.89 | O73: 340 | P73: 240 | Q73: 240 | R73: 240 | S73: 280 | T73: 286.51 | U73: 300 | V73: 260 | W73: 277.7 | X73: 280 | Y73: 9
A74: 10 | B74: Powdered Milk NIDO 390 gm Polybag | C74: Each | D74: 1144 | E74: 1144 | F74: 1144 | G74: 1130 | H74: 1130 | I74: 1130 | J74: 1120 | K74: 1145.7 | L74: 1160 | M74: 1170 | N74: 1173.32 | O74: 1180 | P74: 1150 | Q74: 1150 | R74: 1150 | S74: 1100 | T74: 1100 | U74: 1100 | V74: 1150 | W74: 1155.45 | X74: 1200 | Y74: 10
A75: 11 | B75: Eggs Hen (Farm) | C75: 1 Dozen | D75: 250 | E75: 257.7 | F75: 270 | G75: 240 | H75: 240 | I75: 240 | J75: 255 | K75: 259.82 | L75: 270 | M75: 240 | N75: 245.78 | O75: 250 | P75: 260 | Q75: 260 | R75: 260 | S75: 260 | T75: 273.17 | U75: 280 | V75: 240 | W75: 269.74 | X75: 280 | Y75: 11
A76: 12 | B76: Mustard Oil (Average Quality) | C76: 1 Kg | D76: 560 | E76: 572.17 | F76: 580 | G76: 570 | H76: 570 | I76: 570 | J76: 520 | K76: 566.65 | L76: 650 | M76: 480 | N76: 486.58 | O76: 500 | P76: 460 | Q76: 460 | R76: 460 | S76: 480 | T76: 480 | U76: 480 | V76: 600 | W76: 638.65 | X76: 650 | Y76: 12
... A115: 51 | B115: Toilet Soap LIFEBUOY 115 gm | C115: Each | D115: 116.17 | E115: 116.17 | F115: 116.17 | G115: 116.17 | H115: 116.17 | I115: 116.17 | J115: 116.18 | K115: 116.18 | L115: 116.18 | M115: 116.17 | N115: 116.17 | O115: 116.17 | P115: 116.17 | Q115: 116.17 | R115: 116.17 | S115: 118.6 | T115: 118.6 | U115: 118.6 | V115: 116.87 | W115: 116.87 | X115: 116.87 | Y115: 51
D117: APPENDIX-A
D118: CONSUMER PRICES OF ESSENTIAL ITEMS
...

Sheet CuPrCrPrices
A1: Serial No. | B1: Item Description | C1: Current week | D1: Previous week | E1: Coressponding week
A2: 1 | B2: Wheat Flour Bag | C2: 2582.5 | D2: 2578.86 | E2: 1483.11
A3: 2 | B3: Rice Basmati Broken (Average Quality) | C3: 217.51 | D3: 217.51 | E3: 207.53
A4: 3 | B4: Rice IRRI-6/9 (Sindh/Punjab) | C4: 154.57 | D4: 155.38 | E4: 154.41
A5: 4 | B5: Bread plain (Small Size) | C5: 119.38 | D5: 119.38 | E5: 108.83
A6: 5 | B6: Beef with Bone (Average Quality) | C6: 1257.6 | D6: 1257.6 | E6: 1112.08
A7: 6 | B7: Mutton (Average Quality) | C7: 2373.74 | D7: 2373.74 | E7: 2046.01
A8: 7 | B8: Chicken Farm Broiler (Live) | C8: 365.27 | D8: 383.11 | E8: 423.39
A9: 8 | B9: Milk fresh (Un-boiled) | C9: 217.48 | D9: 217.29 | E9: 201.5
A10: 9 | B10: Curd (Dahi) Loose | C10: 253.38 | D10: 253.16 | E10: 236.45
A11: 10 | B11: Powdered Milk NIDO 390 gm Polybag | C11: 1155.74 | D11: 1155.06 | E11: 1083.45
A12: 11 | B12: Eggs Hen (Farm) | C12: 257.33 | D12: 239.8 | E12: 284.64
A13: 12 | B13: Mustard Oil (Average Quality) | C13: 551.88 | D13: 549.42 | E13: 526.51
... A52: 51 | B52: Toilet Soap LIFEBUOY 115 gm | C52: 116.34 | D52: 116.34 | E52: 110.48

Sheet Appendix-B
A1: APPENDIX-B
A2: A: Retail Prices of Fertilizers (50 kg/bag) for the Week Ended on 23-07-2026
A4: No. | B4: Description | H4: Rawal-pindi | I4: Gujran-wala | J4: Lahore | K4: Faisal-abad | L4: Sar-godha | M4: Multan | N4: Baha-walpur | O4: Hyder-abad | P4: Sukkur | Q4: Larkana | R4: Pesha-war | S4: Bannu | T4: Quetta | U4: Average Price for 23-07-26 16-07-26 24-07-25 | X4: % Change over 16-07-26 24-07-25
A5: 1 | B5: Sona Urea | H5: 5200 | I5: 4600 | J5: 4525 | K5: 4600 | L5: 4633.27 | M5: 4449.72 | N5: 4500 | O5: 4649.73 | P5: 4600 | Q5: 4466.42 | R5: 4600 | S5: 4650 | T5: 5099.35 | U5: =GEOMEAN(H5:T5) -> 4654.5756 | V5: =GEOMEAN(H39:T39) -> 4637.0635 | W5: =GEOMEAN(H47:T47) -> 4414.5714 | X5: =U5/V5*100-100 -> 0.37765519 | Y5: =U5/W5*100-100 -> 5.4366367
A6: 2 | B6: Other Urea (Tara, Sarsabz, Shandar etc) | H6: 5050 | I6: 4550 | J6: 4450 | K6: 4550 | L6: 4533.27 | M6: 4349.71 | N6: 4483.27 | O6: N.A. | P6: 4600 | Q6: N.A. | R6: 4450 | S6: 4300 | T6: N.A. | U6: =GEOMEAN(H6:T6) -> 4527.6487 | V6: =GEOMEAN(H40:T40) -> 4513.9707 | W6: =GEOMEAN(H48:T48) -> 4278.7458 | X6: =U6/V6*100-100 -> 0.30301579 | Y6: =U6/W6*100-100 -> 5.8171942
A7: 3 | B7: Calcium Ammonium Nitrate | H7: 5100 | I7: 4300 | J7: 4400 | K7: N.A. | L7: 4233.27 | M7: 4149.7 | N7: 3766.37 | O7: 4300 | P7: 4250 | Q7: N.A. | R7: N.A. | S7: N.A. | T7: N.A. | U7: =GEOMEAN(H7:T7) -> 4299.0307 | V7: =GEOMEAN(H41:T41) -> 4275.6576 | W7: =GEOMEAN(H49:T49) -> 4061.6366 | X7: =U7/V7*100-100 -> 0.54665468 | Y7: =U7/W7*100-100 -> 5.8447875
A8: 4 | B8: S.S Phosphate, Gr. 18% | H8: N.A. | I8: 4800 | J8: 4700 | K8: 4800 | L8: 4733.27 | M8: N.A. | N8: N.A. | O8: 2949.58 | P8: N.A. | Q8: 4130.5 | R8: 4800 | S8: N.A. | T8: N.A. | U8: =GEOMEAN(H8:T8) -> 4360.488 | V8: =GEOMEAN(H42:T42) -> 4365.1826 | W8: =GEOMEAN(H50:T50) -> 3121.8655 | X8: =U8/V8*100-100 -> -0.10754767 | Y8: =U8/W8*100-100 -> 39.675715
A9: 5 | B9: Sulphate of Potash | H9: N.A. | I9: 14000 | J9: 15300 | K9: 15000 | L9: 15800 | M9: 14849.92 | N9: 13331.23 | O9: N.A. | P9: N.A. | Q9: 16100 | R9: 15000 | S9: N.A. | T9: N.A. | U9: =GEOMEAN(H9:T9) -> 14898.238 | V9: =GEOMEAN(H43:T43) -> 14772.295 | W9: =GEOMEAN(H51:T51) -> 12341.433 | X9: =U9/V9*100-100 -> 0.85256382 | Y9: =U9/W9*100-100 -> 20.717248
A10: 6 | B10: Nitro. Phosphate | H10: N.A. | I10: 10200 | J10: 10700 | K10: 10300 | L10: 10500 | M10: 9749.87 | N10: 9863.14 | O10: 10049.88 | P10: 10200 | Q10: 9463.58 | R10: 10200 | S10: N.A. | T10: N.A. | U10: =GEOMEAN(H10:T10) -> 10116.822 | V10: =GEOMEAN(H44:T44) -> 10047.167 | W10: =GEOMEAN(H52:T52) -> 8168.7912 | X10: =U10/V10*100-100 -> 0.69328208 | Y10: =U10/W10*100-100 -> 23.847237
A11: 7 | B11: DIA Amun. Phosphate | H11: 16000 | I11: 16300 | J11: 16200 | K11: 16000 | L11: 16500 | M11: 15849.92 | N11: 16500 | O11: 16000 | P11: 16200 | Q11: 15671.36 | R11: 16200 | S11: 16500 | T11: 15899.79 | U11: =GEOMEAN(H11:T11) -> 16138.067 | V11: =GEOMEAN(H45:T45) -> 16029.199 | W11: =GEOMEAN(H53:T53) -> 13109.981 | X11: =U11/V11*100-100 -> 0.67918179 | Y11: =U11/W11*100-100 -> 23.097563
A12: 8 | B12: Nitro. Phosph. & Pot. (Npk) | H12: 9900 | I12: N.A. | J12: 11600 | K12: 9600 | L12: 10783.31 | M12: 9849.87 | N12: 11200 | O12: N.A. | P12: N.A. | Q12: N.A. | R12: 11000 | S12: 10300 | T12: 10399.68 | U12: =GEOMEAN(H12:T12) -> 10495.464 | V12: =GEOMEAN(H46:T46) -> 10441.354 | W12: =GEOMEAN(H54:T54) -> 9042.8405 | X12: =U12/V12*100-100 -> 0.51822724 | Y12: =U12/W12*100-100 -> 16.063801
A14: B: Retail Prices of Cement (50 kg/bag) for the Week Ended on 23-07-2026
A16: No. | B16: Description | D16: Islam-abad | E16: Rawal-pindi | F16: Gujran-wala | G16: Sialkot | H16: Lahore | I16: Faisal-abad | J16: Sar-godha | K16: Multan | L16: Baha-walpur | M16: Karachi | N16: Hyder-abad | O16: Sukkur | P16: Larkana | Q16: Pesha-war | R16: Bannu | S16: Quetta | T16: Khuz-dar | U16: Average Price for 23-07-26 16-07-26 24-07-25 | X16: % Change over 16-07-26 24-07-25
A17: 1 | B17: Cement | D17: 1490.76 | E17: 1486.63 | F17: 1550 | G17: 1550 | H17: 1559.96 | I17: 1500 | J17: 1583.33 | K17: 1569.98 | L17: 1546.66 | M17: 1468.97 | N17: 1514.98 | O17: 1600 | P17: 1523.33 | Q17: 1537.67 | R17: 1470 | S17: 1519.98 | T17: 1650 | U17: =GEOMEAN(D17:T17) -> 1535.9011 | V17: 1521.5 | W17: 1406.38 | X17: =U17/V17*100-100 -> 0.94650645 | Y17: =U17/W17*100-100 -> 9.2095377
A19: C: Prices of CNG (per litre for Punjab and per kg otherwise) for the Week Ended on 23-07-2026
A21: No. | B21: Description | D21: Islam-abad | E21: Rawal-pindi | F21: Gujran-wala | G21: Sialkot | H21: Lahore | I21: Faisal-abad | J21: Sar-godha | K21: Multan | L21: Baha-walpur | M21: Avg. Price per litre | N21: % change over Pre. week | O21: Karachi | P21: Hyder-abad | Q21: Sukkur | R21: Larkana | S21: Pesha-war | T21: Bannu | U21: Quetta | V21: Khuz-dar | W21: Avg. Price per kg | X21: % change over Pre. week
A22: 1 | B22: CNG | D22: 375 | E22: 287.35 | F22: 142.99 | G22: 146.9 | H22: 138 | I22: 141.99 | J22: 145.99 | K22: 139.9 | L22: 138.6 | M22: =GEOMEAN(D22:L22) -> 171.08077 | N22: =M22/M38*100-100 -> 0 | O22: 318.26 | P22: 300 | Q22: 300 | R22: 295 | S22: 349.9 | T22: 352 | U22: 315 | V22: N.A. | W22: =GEOMEAN(O22:V22) -> 317.85923 | X22: =W22/W38*100-100 -> 0
A24: D: Wage Rates for the Week Ended on 23-07-2026
A26: No. | B26: Description | C26: Unit | D26: Islam-abad | E26: Rawal-pindi | F26: Gujran-wala | G26: Sialkot | H26: Lahore | I26: Faisal-abad | J26: Sar-godha | K26: Multan | L26: Baha-walpur | M26: Karachi | N26: Hyder-abad | O26: Sukkur | P26: Larkana | Q26: Pesha-war | R26: Bannu | S26: Quetta | T26: Khuz-dar | U26: Average Price for 23-07-26 16-07-26 24-07-25 | X26: % Change over 16-07-26 24-07-25
A27: 1 | B27: Painter | C27: Daily | D27: 2364.08 | E27: 2207.45 | F27: 1800 | G27: 1800 | H27: 2246.86 | I27: 1650.96 | J27: 1600 | K27: 1521.67 | L27: 1432.57 | M27: 1721.19 | N27: 1722.48 | O27: 1600 | P27: 1565.95 | Q27: 2064.56 | R27: 1800 | S27: 1792.56 | T27: 1500 | U27: =GEOMEAN(D27:T27) -> 1768.7939 | V27: 1768.79 | W27: 1697.05 | X27: =U27/V27*100-100 -> 0.00021833078 | Y27: =U27/W27*100-100 -> 4.2275632
A28: 2 | B28: Mason (Raj) | C28: Daily | D28: 2440.11 | E28: 2299.77 | F28: 2200 | G28: 2000 | H28: 2460.86 | I28: 1993.31 | J28: 2000 | K28: 1732.7 | L28: 1864.34 | M28: 2481.51 | N28: 1957.26 | O28: 1600 | P28: 1930.98 | Q28: 2420.94 | R28: 2200 | S28: 2193.92 | T28: 1766.03 | U28: =GEOMEAN(D28:T28) -> 2073.614 | V28: 2073.61 | W28: 1966.06 | X28: =U28/V28*100-100 -> 0.00019328882 | Y28: =U28/W28*100-100 -> 5.4705354
A29: 3 | B29: Labourer | C29: Daily | D29: 1500 | E29: 1500 | F29: 1500 | G29: 1500 | H29: 1746.91 | I29: 1266.45 | J29: 1466.48 | K29: 1032.28 | L29: 1000 | M29: 1477.52 | N29: 1032.28 | O29: 900 | P29: 900 | Q29: 1465.9 | R29: 1200 | S29: 1449.43 | T29: 1232.45 | U29: =GEOMEAN(D29:T29) -> 1279.2713 | V29: 1279.27 | W29: 1206.74 | X29: =U29/V29*100-100 -> 0.00010371424 | Y29: =U29/W29*100-100 -> 6.0105182
A30: 4 | B30: Plumber | C30: Daily | D30: 2238.23 | E30: 2292.65 | F30: 1800 | G30: 1800 | H30: 2037.3 | I30: 1500 | J30: 2466.21 | K30: 1727.21 | L30: 1465.9 | M30: 2365.63 | N30: 2056.57 | O30: 1600 | P30: 1565.95 | Q30: 2500 | R30: 1600 | S30: 1698.04 | T30: 1500 | U30: =GEOMEAN(D30:T30) -> 1863.475 | V30: 1863.47 | W30: 1749.84 | X30: =U30/V30*100-100 -> 0.00026727867 | Y30: =U30/W30*100-100 -> 6.4940212
A31: 5 | B31: Electrician | C31: P/Point | D31: 487 | E31: 461.48 | F31: 250 | G31: 230 | H31: 318.74 | I31: 265.66 | J31: 273.29 | K31: 223.61 | L31: 200 | M31: 400.28 | N31: 393.22 | O31: 200 | P31: 239.57 | Q31: 332.47 | R31: 193.1 | S31: 317.37 | T31: 293.18 | U31: =GEOMEAN(D31:T31) -> 286.84307 | V31: 286.84 | W31: 272.61 | X31: =U31/V31*100-100 -> 0.0010716198 | Y31: =U31/W31*100-100 -> 5.2210388
A32: E: Wheat Rates for the Week Ended on 23.07.2026
A33: No. | B33: Description | D33: Unit | E33: Islam-abad | F33: Rawal-pindi | G33: Gujran-wala | H33: Sialkot | I33: Lahore | J33: Faisal-abad | K33: Sar-godha | L33: Multan | M33: Baha-walpur | N33: Karachi | O33: Hyder-abad | P33: Sukkur | Q33: Larkana | R33: Pesha-war | S33: Bannu | T33: Quetta | U33: Khuzdar | V33: Average Price for 23.07.2026 16.07.2026 | X33: % Change over 16.07.2026
A34: 1 | B34: Wheat | D34: 10 kg | E34: 1324.84 | F34: 1324.84 | G34: 1158.27 | H34: 1125 | I34: 1120 | J34: 1075 | K34: 1071.66 | L34: 1158.18 | M34: 1116.6 | N34: 1160 | O34: 1200 | P34: 1050 | Q34: 1139.91 | R34: 1350 | S34: 1340 | T34: 1199.97 | U34: 1200 | V34: =GEOMEAN(E34:U34) -> 1179.5432 | W34: 1164.1648 | X34: =+ROUND(V34/W34*100-100,2) -> 1.32
A35: 2 | B35: Wheat Flour (Fine) | D35: 1 kg | E35: 167.9 | F35: 158.62 | G35: 136.65 | H35: 146 | I35: 162.82 | J35: 140 | K35: 130 | L35: 146.9 | M35: 151.54 | N35: 150.04 | O35: 159.16 | P35: 150 | Q35: 130 | R35: 149.99 | S35: 147 | T35: 159 | U35: 140 | V35: =GEOMEAN(E35:U35) -> 148.18515 | W35: 146.58836 | X35: =+ROUND(V35/W35*100-100,2) -> 1.09
B36: N.A. stands for Not Available.
D38: 375 | E38: 287.35 | F38: 142.99 | G38: 146.9 | H38: 138 | I38: 141.99 | J38: 145.99 | K38: 139.9 | L38: 138.6 | M38: =GEOMEAN(D38:L38) -> 171.08077 | O38: 318.26 | P38: 300 | Q38: 300 | R38: 295 | S38: 349.9 | T38: 352 | U38: 315 | W38: =GEOMEAN(O38:V38) -> 317.85923
H39: 5100 | I39: 4600 | J39: 4525 | K39: 4600 | L39: 4633.27 | M39: 4449.72 | N39: 4500 | O39: 4649.73 | P39: 4514.98 | Q39: 4466.42 | R39: 4550 | S39: 4650 | T39: 5099.35
H40: 5050 | I40: 4550 | J40: 4450 | K40: 4550 | L40: 4533.27 | M40: 4349.71 | N40: 4483.27 | O40: N.A. | P40: 4500 | Q40: N.A. | R40: 4413.32 | S40: 4300 | T40: N.A.
H41: 5000 | I41: 4300 | J41: 4400 | K41: N.A. | L41: 4233.27 | M41: 4149.7 | N41: 3766.37 | O41: 4300 | P41: 4150 | Q41: N.A. | R41: N.A. | S41: N.A. | T41: N.A.
H42: N.A. | I42: 4800 | J42: 4700 | K42: 4800 | L42: 4733.27 | M42: N.A. | N42: N.A. | O42: 2949.58 | P42: N.A. | Q42: 4161.73 | R42: 4800 | S42: N.A. | T42: N.A.
H43: N.A. | I43: 13000 | J43: 15300 | K43: 15000 | L43: 15800 | M43: 14849.92 | N43: 13331.23 | O43: N.A. | P43: N.A. | Q43: 16200 | R43: 15000 | S43: N.A. | T43: N.A.
H44: N.A. | I44: 10200 | J44: 10700 | K44: 10300 | L44: 10300 | M44: 9749.87 | N44: 9863.14 | O44: 10049.88 | P44: 9800 | Q44: 9463.58 | R44: 10100 | S44: N.A. | T44: N.A.
H45: 15500 | I45: 16300 | J45: 16200 | K45: 16000 | L45: 15566.65 | M45: 15849.92 | N45: 16500 | O45: 16000 | P45: 15800 | Q45: 16100 | R45: 16200 | S45: 16500 | T45: 15899.79
H46: 9900 | I46: N.A. | J46: 11600 | K46: 9600 | L46: 10783.31 | M46: 9849.87 | N46: 11200 | O46: N.A. | P46: N.A. | Q46: N.A. | R46: 10500 | S46: 10300 | T46: 10399.68
H47: 4450 | I47: 4250 | J47: 4400 | K47: 4400 | L47: 4416.6 | M47: 4224.93 | N47: 4300 | O47: 4549.73 | P47: 4200 | Q47: 4265.64 | R47: 4300 | S47: 4350 | T47: 5399.38
H48: 4300 | I48: 4230 | J48: 4300 | K48: 4350 | L48: 4466.6 | M48: 4124.92 | N48: 4300 | O48: N.A. | P48: 4224.93 | Q48: N.A. | R48: 4200 | S48: 4300 | T48: N.A.
...

Sheet Annexure-V
A1: Annexure-V
A3: Quintile/Commodity wise Indices and their % Change over
A4: Previous and Corresponding Weeks of SPI for 51 Items
A5: Commodity Groups | B5: Index for the Week 23-07-2026 16-07-2026 24-07-2025 | E5: % Change in 23-07-2026 over 16-07-2026 24-07-2025
A6: Quintile - I
A7: Food | B7: 314.22 | C7: 310.4 | D7: 282.67 | E7: =B7/C7*100-100 -> 1.2306701 | F7: =B7/D7*100-100 -> 11.161425
A8: Non-food | B8: 435.12 | C8: 433.99 | D8: 400.45 | E8: =B8/C8*100-100 -> 0.26037466 | F8: =B8/D8*100-100 -> 8.65776
A9: Other Non-food | B9: 315.67 | C9: 315.67 | D9: 289.94 | E9: =B9/C9*100-100 -> 0 | F9: =B9/D9*100-100 -> 8.8742498
A10: Utility | B10: 632.77 | C10: 632.77 | D10: 588.84 | E10: =B10/C10*100-100 -> 0 | F10: =B10/D10*100-100 -> 7.4604307
A11: Transport | B11: 442.73 | C11: 420.23 | D11: 368.18 | E11: =B11/C11*100-100 -> 5.3542108 | F11: =B11/D11*100-100 -> 20.248248
A12: General | B12: 349.8 | C12: 346.78 | D12: 317.34 | E12: =B12/C12*100-100 -> 0.87086914 | F12: =B12/D12*100-100 -> 10.228777
A13: Quintile - II
A14: Food | B14: 314.19 | C14: 310.66 | D14: 282.61 | E14: =B14/C14*100-100 -> 1.1362905 | F14: =B14/D14*100-100 -> 11.17441
A15: Non-food | B15: 437.77 | C15: 435.7 | D15: 397.69 | E15: =B15/C15*100-100 -> 0.47509754 | F15: =B15/D15*100-100 -> 10.078202
A16: Other Non-food | B16: 321.68 | C16: 321.69 | D16: 296.03 | E16: =B16/C16*100-100 -> -0.0031085828 | F16: =B16/D16*100-100 -> 8.6646624
A17: Utility | B17: 586.19 | C17: 586.19 | D17: 535.55 | E17: =B17/C17*100-100 -> 0 | F17: =B17/D17*100-100 -> 9.4556997
A18: Transport | B18: 442.72 | C18: 420.23 | D18: 368.18 | E18: =B18/C18*100-100 -> 5.3518311 | F18: =B18/D18*100-100 -> 20.245532
A19: General | B19: 351.58 | C19: 348.49 | D19: 317.42 | E19: =B19/C19*100-100 -> 0.88668254 | F19: =B19/D19*100-100 -> 10.761767
A20: Quintile - III
A21: Food | B21: 313.46 | C21: 310.41 | D21: 282.93 | E21: =B21/C21*100-100 -> 0.98257144 | F21: =B21/D21*100-100 -> 10.790655
A22: Non-food | B22: 505.01 | C22: 502.26 | D22: 471.11 | E22: =B22/C22*100-100 -> 0.54752519 | F22: =B22/D22*100-100 -> 7.1957717
A23: Other Non-food | B23: 328.85 | C23: 328.93 | D23: 300.97 | E23: =B23/C23*100-100 -> -0.024321284 | F23: =B23/D23*100-100 -> 9.2633817
A24: Utility | B24: 713.73 | C24: 713.73 | D24: 685.32 | E24: =B24/C24*100-100 -> 0 | F24: =B24/D24*100-100 -> 4.1455087
A25: Transport | B25: 442.62 | C25: 420.26 | D25: 368.21 | E25: =B25/C25*100-100 -> 5.3205159 | F25: =B25/D25*100-100 -> 20.208577
A26: General | B26: 371.94 | C26: 368.99 | D26: 340.39 | E26: =B26/C26*100-100 -> 0.79947966 | F26: =B26/D26*100-100 -> 9.2687799
A27: Quintile - IV
A28: Food | B28: 311.9 | C28: 309.12 | D28: 282.21 | E28: =B28/C28*100-100 -> 0.89932712 | F28: =B28/D28*100-100 -> 10.520534
A29: Non-food | B29: 456.29 | C29: 452.67 | D29: 424.71 | E29: =B29/C29*100-100 -> 0.79969956 | F29: =B29/D29*100-100 -> 7.435662
A30: Other Non-food | B30: 332.5 | C30: 332.63 | D30: 303.26 | E30: =B30/C30*100-100 -> -0.039082464 | F30: =B30/D30*100-100 -> 9.6418914
A31: Utility | B31: 575.28 | C31: 575.28 | D31: 557.59 | E31: =B31/C31*100-100 -> 0 | F31: =B31/D31*100-100 -> 3.172582
A32: Transport | B32: 442.77 | C32: 420.21 | D32: 368.17 | E32: =B32/C32*100-100 -> 5.3687442 | F32: =B32/D32*100-100 -> 20.262379
A33: General | B33: 358.68 | C33: 355.62 | D33: 328.38 | E33: =B33/C33*100-100 -> 0.86046904 | F33: =B33/D33*100-100 -> 9.2271149
A34: Quintile - V
A35: Food | B35: 314.49 | C35: 312.02 | D35: 286.24 | E35: =B35/C35*100-100 -> 0.79161592 | F35: =B35/D35*100-100 -> 9.8693404
A36: Non-food | B36: 422.14 | C36: 417.22 | D36: 389.73 | E36: =B36/C36*100-100 -> 1.179234 | F36: =B36/D36*100-100 -> 8.3160137
A37: Other Non-food | B37: 348.5 | C37: 348.94 | D37: 308.01 | E37: =B37/C37*100-100 -> -0.12609618 | F37: =B37/D37*100-100 -> 13.145677
A38: Utility | B38: 459.61 | C38: 459.61 | D38: 452.18 | E38: =B38/C38*100-100 -> 0 | F38: =B38/D38*100-100 -> 1.643151
A39: Transport | B39: 442.96 | C39: 420.14 | D39: 368.12 | E39: =B39/C39*100-100 -> 5.4315228 | F39: =B39/D39*100-100 -> 20.330327
A40: General | B40: 358.89 | C40: 355.4 | D40: 328.92 | E40: =B40/C40*100-100 -> 0.98199212 | F40: =B40/D40*100-100 -> 9.1116381
A41: Quintile - VI (Overall/Combined)
...

Sheet Page 1
A1: Annexure-III
A3: Government of Pakistan
A7: Pakistan Bureau of Statistics
A9: Subject: Sensitive Price Indicator (SPI) for the week ended on 23-07-2026.
B12: The weekly SPI with base 2015-16=100 covering 17 urban centres and 51 essential items
A13: for all expenditure groups/quintiles and combined has been computed.
A16: 2. | B16: For the week ended on July 23, 2026, the SPI and percentage changes by
A17: Consumption groups/quintiles and combined are given below:
B19: SPI (51 items) 2015-16=100
B20: Expenditure Group (Quintile) | D20: SPI for week ended on 23-07-2026 16-07-26 24-07-25 | G20: % change over 16-07-26 24-07-25
B21: Q1 (Upto Rs. 17,732) | D21: 349.8 | E21: 346.78 | F21: 317.34 | G21: =D21/E21*100-100 -> 0.87086914 | H21: =D21/F21*100-100 -> 10.228777
B22: Q2 (Rs. 17,733 - 22,888) | D22: 351.58 | E22: 348.49 | F22: 317.42 | G22: =D22/E22*100-100 -> 0.88668254 | H22: =D22/F22*100-100 -> 10.761767
B23: Q3 (Rs. 22,889 - 29,517) | D23: 371.94 | E23: 368.99 | F23: 340.39 | G23: =D23/E23*100-100 -> 0.79947966 | H23: =D23/F23*100-100 -> 9.2687799
B24: Q4 (Rs. 29,518 - 44,175) | D24: 358.68 | E24: 355.62 | F24: 328.38 | G24: =D24/E24*100-100 -> 0.86046904 | H24: =D24/F24*100-100 -> 9.2271149
B25: Q5 (Above Rs. 44,175) | D25: 358.89 | E25: 355.4 | F25: 328.92 | G25: =D25/E25*100-100 -> 0.98199212 | H25: =D25/F25*100-100 -> 9.1116381
B26: Combined | D26: 360.88 | E26: 357.61 | F26: 329.09 | G26: =D26/E26*100-100 -> 0.91440396 | H26: =D26/F26*100-100 -> 9.6599714
A29: 3. | B29: The trend of weekly SPI with base 2015-16=100 during the last 10 weeks as compared to
A30: the respective previous as well as corresponding weeks of last year is as under:
B32: SPI (51 items) 2015-16=100
B33: Week ended on | C33: SPI for lowest expenditure group | D33: % change over Pr. Week Cor. Week | F33: Combined SPI | G33: % change over Pr. Week Cor. Week
B34: 14-05-2026 | C34: 335.77 | D34: =C34/334.45*100-100 -> 0.39467783 | E34: =C34/300.18*100-100 -> 11.85622 | F34: 358.71 | G34: =F34/357.04*100-100 -> 0.46773471 | H34: =F34/312.34*100-100 -> 14.846001
B35: 21-05-2026 | C35: 335.56 | D35: =C35/335.77*100-100 -> -0.062542812 | E35: =C35/298.17*100-100 -> 12.539826 | F35: 357.54 | G35: =F35/358.71*100-100 -> -0.32616877 | H35: =F35/309.8*100-100 -> 15.409942
B36: 28-05-2026 | C36: 335.56 | D36: =C36/335.56*100-100 -> 0 | E36: =C36/298.99*100-100 -> 12.231178 | F36: 357.54 | G36: =F36/357.54*100-100 -> 0 | H36: =F36/309.85*100-100 -> 15.391318
B37: 04-06-2026 | C37: 336.62 | D37: =C37/335.56*100-100 -> 0.31588986 | E37: =C37/299.44*100-100 -> 12.416511 | F37: 355.55 | G37: =F37/357.54*100-100 -> -0.55658108 | H37: =F37/309.51*100-100 -> 14.875125
B38: 11-06-2026 | C38: 337.25 | D38: =C38/336.62*100-100 -> 0.18715466 | E38: =C38/299.58*100-100 -> 12.574271 | F38: 356.11 | G38: =F38/355.55*100-100 -> 0.15750246 | H38: =F38/310.35*100-100 -> 14.744643
B39: 18-06-2026 | C39: 339.41 | D39: =C39/337.25*100-100 -> 0.64047443 | E39: =C39/299.39*100-100 -> 13.36718 | F39: 357.76 | G39: =F39/356.11*100-100 -> 0.46333998 | H39: =F39/309.8*100-100 -> 15.480955
B40: 02-07-2026 | C40: 344.22 | D40: =C40/339.41*100-100 -> 1.4171651 | E40: =C40/301.6*100-100 -> 14.1313 | F40: 354.24 | G40: =F40/357.76*100-100 -> -0.98389982 | H40: =F40/312.06*100-100 -> 13.516631
B41: 09-07-2026 | C41: 342.98 | D41: =C41/344.22*100-100 -> -0.36023473 | E41: =C41/304.79*100-100 -> 12.529939 | F41: 352.66 | G41: =F41/354.24*100-100 -> -0.44602529 | H41: =F41/315.03*100-100 -> 11.944894
B42: 16-07-2026 | C42: 346.78 | D42: =C42/342.98*100-100 -> 1.1079363 | E42: =C42/305.19*100-100 -> 13.627576 | F42: 357.61 | G42: =F42/352.66*100-100 -> 1.4036182 | H42: =F42/316.23*100-100 -> 13.085413
B43: 23-07-2026 | C43: 349.8 | D43: =C43/346.78*100-100 -> 0.87086914 | E43: =C43/317.34*100-100 -> 10.228777 | F43: 360.88 | G43: =F43/357.61*100-100 -> 0.91440396 | H43: =F43/329.09*100-100 -> 9.6599714
A46: 4. | B46: A statement showing citywise prices of essential items pertaining to 17 urban centres is
A47: placed at Appendix-A.

Sheet Page 2
A1: 5 | B1: The comparative changes in prices i.e. increase, decrease and unchanged for the week ended on 23-07-2026 over
A2: previous and corresponding weeks ended on 16-07-2026 and 24-07-2025 repectively are as follows:
B4: Sr. | C4: Items | D4: Units | E4: Prices in Rs. on 23.07.26 16.07.26 24.07.25 | H4: %change col. 3 over 16.07.26 24.07.25 | J4: Weight of expenditure group in % Lowest Combined | L4: Impact of expenditure group in % points Lowest Combined
C5: 1 | D5: 2 | E5: 3 | F5: 4 | G5: 5 | H5: 6 | I5: 7 | J5: 8 | K5: 9 | L5: 10 | M5: 11
B6: i. Average prices of the following 22 items registered INCREASE.
B7: 1 | C7: Tomatoes | D7: 1 Kg | E7: 350.46 | F7: 250.47 | G7: 99.27 | H7: 39.92 | I7: 253.04 | J7: 1.4395 | K7: 0.9816 | L7: 0.88341694 | M7: 0.58415315
B8: 2 | C8: Hi-Speed Diesel | D8: Per Litre | E8: 376.64 | F8: 325.06 | G8: 285.51 | H8: 15.87 | I8: 31.92 | J8: 0.0114 | K8: 0.0874 | L8: 0.0021627638 | M8: 0.015939076
B9: 3 | C9: Eggs Hen (Farm) | D9: 1 Dozen | E9: 257.33 | F9: 239.8 | G9: 284.64 | H9: 7.31 | I9: -9.59 | J9: 1.178 | K9: 1.4424 | L9: 0.063758278 | M9: 0.075724592
B10: 4 | C10: Petrol Super | D10: Per Litre | E10: 328.89 | F10: 312.53 | G10: 273.34 | H10: 5.23 | I10: 20.32 | J10: 1.4673 | K10: 6.7018 | L10: 0.093835114 | M10: 0.4155345
B11: 5 | C11: Potatoes | D11: 1 Kg | E11: 56.6 | F11: 54.58 | G11: 84.09 | H11: 3.7 | I11: -32.69 | J11: 2.2955 | K11: 1.2157 | L11: 0.017100253 | M11: 0.0087804733
B12: 6 | C12: LPG 11.67 kg Cylinder | D12: Each | E12: 4495.31 | F12: 4454.62 | G12: 3060.74 | H12: 0.91 | I12: 46.87 | J12: 0.6145 | K12: 1.437 | L12: -0.0055366754 | M12: -0.012555518
B13: 7 | C13: Cooked Daal at Average Hotel | D13: Per Plate | E13: 175.48 | F13: 174.23 | G13: 167.17 | H13: 0.72 | I13: 4.97 | J13: 1.3118 | K13: 1.3014 | L13: 0.00155719 | M13: 0.0015100177
B14: 8 | C14: Tea Lipton Yellow Label 190 gm Packet | D14: Each | E14: 456.7 | F14: 454.04 | G14: 447.07 | H14: 0.59 | I14: 2.15 | J14: 3.1478 | K14: 2.3913 | L14: 0.014706794 | M14: 0.010849757
B15: 9 | C15: Mustard Oil (Average Quality) | D15: 1 Kg | E15: 551.88 | F15: 549.42 | G15: 526.51 | H15: 0.45 | I15: 4.82 | J15: 0.0216 | K15: 0.0341 | L15: 2.8836851e-05 | M15: 5.5926582e-05
B16: 10 | C16: Garlic (Lehsun) | D16: 1 Kg | E16: 370.35 | F16: 368.84 | G16: 377.25 | H16: 0.41 | I16: -1.83 | J16: 0.6807 | K16: 0.5795 | L16: 0.00037487907 | M16: 0.0003075962
B17: 11 | C17: Cooked Beef at Average Hotel | D17: Per Plate | E17: 322.33 | F17: 321.18 | G17: 307.63 | H17: 0.36 | I17: 4.78 | J17: 0.5033 | K17: 1.0497 | L17: 0.00034604221 | M17: 0.00075500885
B18: 12 | C18: Vegetable Ghee DALDA/HABIB or Other superior Quality 1 kg Pouch | D18: Each | E18: 607.35 | F18: 605.67 | G18: 568.47 | H18: 0.28 | I18: 6.84 | J18: 3.2833 | K18: 1.4648 | L18: 0.0045850593 | M18: 0.0019574304
... B28: 22 | C28: Gur (Average Quality) | D28: 1 Kg | E28: 228.19 | F28: 228.09 | G28: 239.21 | H28: 0.04 | I28: -4.61 | J28: 0.2341 | K28: 0.1075 | L28: 2.8836851e-05 | M28: 2.7963291e-05
B29: TOTAL | J29: =SUM(J7:J28) -> 52.4187 | K29: =SUM(K7:K28) -> 52.5813 | L29: =SUM(L7:L28) -> 0.98036643 | M29: =SUM(M7:M28) -> 1.0482878
B30: ii. Average prices of the following 8 items registered DECREASE.
B31: 1 | C31: Chicken Farm Broiler (Live) | D31: 1 Kg | E31: 365.27 | F31: 383.11 | G31: 423.39 | H31: -4.66 | I31: -13.73 | J31: 2.9269 | K31: 3.8681 | L31: -0.1021978 | M31: -0.13098005
B32: 2 | C32: Bananas (Kela) Local | D32: 1 Dozen | E32: 187.86 | F32: 191.15 | G32: 167.64 | H32: -1.72 | I32: 12.06 | J32: 0.7124 | K32: 0.9413 | L32: 0.0010669635 | M32: 0.0013702013
B33: 3 | C33: Pulse Moong (Washed) | D33: 1 Kg | E33: 363.28 | F33: 367.24 | G33: 397.77 | H33: -1.08 | I33: -8.67 | J33: 0.8715 | K33: 0.4816 | L33: -0.0016148637 | M33: -0.00086686202
B34: 4 | C34: Pulse Mash (Washed) | D34: 1 Kg | E34: 450.33 | F34: 455.19 | G34: 455.96 | H34: -1.07 | I34: -1.23 | J34: 0.2855 | K34: 0.3269 | L34: -0.00057673702 | M34: -0.00058722911
B35: 5 | C35: Rice IRRI-6/9 (Sindh/Punjab) | D35: 1 Kg | E35: 154.57 | F35: 155.38 | G35: 154.41 | H35: -0.52 | I35: 0.1 | J35: 0.5922 | K35: 0.1671 | L35: -0.00040371592 | M35: -0.00011185316
B36: 6 | C36: Pulse Masoor (Washed) | D36: 1 Kg | E36: 256.32 | F36: 257.36 | G36: 296.5 | H36: -0.4 | I36: -13.55 | J36: 0.6545 | K36: 0.4608 | L36: -0.00066324758 | M36: -0.00044741265
B37: 7 | C37: Sugar Refined | D37: 1 Kg | E37: 148.23 | F37: 148.36 | G37: 180.04 | H37: -0.09 | I37: -17.67 | J37: 5.1148 | K37: 3.1584 | L37: -0.0044408751 | M37: -0.0026565126
B38: 8 | C38: Pulse Gram | D38: 1 Kg | E38: 245.64 | F38: 245.71 | G38: 312.85 | H38: -0.03 | I38: -21.48 | J38: 0.7967 | K38: 0.4711 | L38: 0.00098045294 | M38: 0.00058722911
B39: TOTAL | J39: =SUM(J31:J38) -> 11.9545 | K39: =SUM(K31:K38) -> 9.8753 | L39: =SUM(L31:L38) -> -0.10784982 | M39: =SUM(M31:M38) -> -0.13369249
B40: iii. Average prices of the following 21 items remained UNCHANGED
B41: 1 | C41: Rice Basmati Broken (Average Quality) | D41: 1 Kg | E41: 217.51 | F41: 217.51 | G41: 207.53 | H41: 0 | I41: 4.81 | J41: 2.961 | K41: 1.2636 | L41: 0 | M41: 0
B42: 2 | C42: Bread plain (Small Size) | D42: Each | E42: 119.38 | F42: 119.38 | G42: 108.83 | H42: 0 | I42: 9.69 | J42: 0.1041 | K42: 0.5698 | L42: 0 | M42: 0
B43: 3 | C43: Beef with Bone (Average Quality) | D43: 1 Kg | E43: 1257.6 | F43: 1257.6 | G43: 1112.08 | H43: 0 | I43: 13.09 | J43: 2.4988 | K43: 3.3533 | L43: 0 | M43: 0
B44: 4 | C44: Mutton (Average Quality) | D44: 1 Kg | E44: 2373.74 | F44: 2373.74 | G44: 2046.01 | H44: 0 | I44: 16.02 | J44: 0.5498 | K44: 2.4387 | L44: 0 | M44: 0
B45: 5 | C45: Salt Powdered (NATIONAL/SHAN) 800 gm Packet | D45: Each | E45: 62.37 | F45: 62.37 | G45: 72.6 | H45: 0 | I45: -14.09 | J45: 0.2844 | K45: 0.2279 | L45: 0 | M45: 0
B46: 6 | C46: Chilies Powder NATIONAL 200 gm Packet | D46: Each | E46: 368.65 | F46: 368.65 | G46: 320 | H46: 0 | I46: 15.2 | J46: 1.3896 | K46: 0.8454 | L46: 0 | M46: 0
B47: 7 | C47: Cigarettes Capstan 20'S Packet | D47: Each | E47: 252.06 | F47: 252.06 | G47: 242.42 | H47: 0 | I47: 3.98 | J47: 1.617 | K47: 1.0931 | L47: 0 | M47: 0
B48: 8 | C48: Long Cloth 57" Gul Ahmed/Al Karam | D48: 1 mtr | E48: 688.69 | F48: 688.69 | G48: 656.91 | H48: 0 | I48: 4.84 | J48: 4.2221 | K48: 3.9577 | L48: 0 | M48: 0
B49: 9 | C49: Shirting (Average Quality) | D49: 1 mtr | E49: 544.67 | F49: 544.67 | G49: 499.58 | H49: 0 | I49: 9.03 | J49: 0.0317 | K49: 0.101 | L49: 0 | M49: 0
B50: 10 | C50: Lawn Printed Gul Ahmed/Al Karam | D50: 1 mtr | E50: 680.92 | F50: 680.92 | G50: 656.59 | H50: 0 | I50: 3.71 | J50: 2.3442 | K50: 2.1473 | L50: 0 | M50: 0
...

Sheet MinMaxCities
A1: Names of cities having maximum and minimum prices of SPI for the week ending on 23-07-2026
A2: Sl. No. | B2: Description | C2: Unit | D2: Minimum Prices | E2: Maximum Prices
A3: 1 | B3: 2 | C3: 3 | D3: 4 | E3: 5
A4: 1 | B4: Wheat Flour Bag | C4: 20 Kg | D4: (Rs. 2200) Rawalpindi, Gujranwala, Sialkot, Faisalabad, Sargodha, Multan | E4: (Rs. 2960) Islamabad
A5: 2 | B5: Rice Basmati Broken (Average Quality) | C5: 1 Kg | D5: (Rs. 140) Bannu | E5: (Rs. 300) Quetta
A6: 3 | B6: Rice IRRI-6/9 (Sindh/Punjab) | C6: 1 Kg | D6: (Rs. 110) Larkana | E6: (Rs. 200) Islamabad, Bahawalpur
A7: 4 | B7: Bread plain (Small Size) | C7: Each | D7: (Rs. 100) Sargodha, Bannu | E7: (Rs. 130) Sialkot, Lahore, Karachi, Hyderabad, Sukkur, Quetta
A8: 5 | B8: Beef with Bone (Average Quality) | C8: 1 Kg | D8: (Rs. 1000) Bannu | E8: (Rs. 1550) Islamabad, Rawalpindi
A9: 6 | B9: Mutton (Average Quality) | C9: 1 Kg | D9: (Rs. 1800) Bannu | E9: (Rs. 3000) Lahore
A10: 7 | B10: Chicken Farm Broiler (Live) | C10: 1 Kg | D10: (Rs. 310) Hyderabad | E10: (Rs. 440) Khuzdar
A11: 8 | B11: Milk fresh (Un-boiled) | C11: 1 Ltr | D11: (Rs. 170) Sargodha | E11: (Rs. 270) Peshawar
A12: 9 | B12: Curd (Dahi) Loose | C12: 1 Kg | D12: (Rs. 190) Sialkot | E12: (Rs. 400) Karachi
A13: 10 | B13: Powdered Milk NIDO 390 gm Polybag | C13: Each | D13: (Rs. 1100) Larkana, Bannu | E13: (Rs. 1200) Islamabad, Rawalpindi, Sialkot, Peshawar
A14: 11 | B14: Eggs Hen (Farm) | C14: 1 Dozen | D14: (Rs. 230) Bannu | E14: (Rs. 280) Islamabad, Rawalpindi, Larkana, Peshawar
A15: 12 | B15: Mustard Oil (Average Quality) | C15: 1 Kg | D15: (Rs. 460) Sukkur | E15: (Rs. 720) Islamabad
... A54: 51 | B54: Toilet Soap LIFEBUOY 115 gm | C54: Each | D54: (Rs. 110) Khuzdar | E54: (Rs. 118.6) Larkana

Sheet Impact Combined
A1: Statement showing SPI prices, indices, %changes and impacts for 51 items with Base 2015-16 (Combined)
A2: Current Date = 23/07/2026 ,Previous Date = 16/07/2026 ,Corresponding Date = 24/07/2025 | P2: Summary for the Minister
A3: No. | B3: Item Code | C3: Item Description | D3: Unit | E3: Weighted Base Price | F3: Weight | G3: Weighted Prices (Curr) (Prev) (Corr) | J3: Weighted Price Relatives (Curr) (Prev) (Corr) | M3: Impact with Prev Corr | P3: Item group | Q3: Weight | R3: Impact (current with) previous corresponding
A4: 1 | B4: 01.1.1.04 | C4: Wheat Flour Bag | D4: 20 Kg | E4: 779.92 | F4: 3.9725 | G4: 2536.55 | H4: 2678.83 | I4: 1491.87 | J4: =ROUND(ROUND(ROUND(G4*F4,4)*100/E4,4)/100,4) -> 12.9198 | K4: =ROUND(ROUND(ROUND(H4*F4,4)*100/E4,4)/100,4) -> 13.6445 | L4: =ROUND(ROUND(ROUND(I4*F4,4)*100/E4,4)/100,4) -> 7.5988 | M4: =(J4-K4)/K55*100 -> -0.20228247 | N4: =(J4-L4)/L55*100 -> 1.6168687 | P4: Food | Q4: =SUM(F4:F36) -> 63.4305 | R4: =SUM(M4:M36) -> 0.31055537 | S4: =SUM(N4:N36) -> 5.6558801
A5: 2 | B5: 01.1.1.10 | C5: Rice Basmati Broken (Average Quality) | D5: 1 Kg | E5: 63.21 | F5: 1.2636 | G5: 238.77 | H5: 238.77 | I5: 225.9 | J5: =ROUND(ROUND(ROUND(G5*F5,4)*100/E5,4)/100,4) -> 4.7731 | K5: =ROUND(ROUND(ROUND(H5*F5,4)*100/E5,4)/100,4) -> 4.7731 | L5: =ROUND(ROUND(ROUND(I5*F5,4)*100/E5,4)/100,4) -> 4.5159 | M5: =(J5-K5)/K55*100 -> 0 | N5: =(J5-L5)/L55*100 -> 0.078154223 | P5: Non-food | Q5: =SUM(F37:F43,F46:F49,F52,F54) -> 13.2377 | R5: =SUM(M37:M43,M46:M49,M52,M54) -> -0.0096577527 | S5: =SUM(N37:N43,N46:N49,N52,N54) -> 1.3762679
A6: 3 | B6: 01.1.1.11 | C6: Rice IRRI-6/9 (Sindh/Punjab) | D6: 1 Kg | E6: 46.47 | F6: 0.1671 | G6: 160.75 | H6: 160.86 | I6: 162.39 | J6: =ROUND(ROUND(ROUND(G6*F6,4)*100/E6,4)/100,4) -> 0.578 | K6: =ROUND(ROUND(ROUND(H6*F6,4)*100/E6,4)/100,4) -> 0.5784 | L6: =ROUND(ROUND(ROUND(I6*F6,4)*100/E6,4)/100,4) -> 0.5839 | M6: =(J6-K6)/K55*100 -> -0.00011165032 | N6: =(J6-L6)/L55*100 -> -0.0017928068 | P6: Utility | Q6: =SUM(F44:F45,F53) -> 16.5426 | R6: =SUM(M44:M45,M53) -> 0 | S6: =SUM(N44:N45,N53) -> 1.0853166
A7: 4 | B7: 01.1.1.12 | C7: Bread plain (Small Size) | D7: Each | E7: 42.71 | F7: 0.5698 | G7: 125.75 | H7: 125.75 | I7: 109.78 | J7: =ROUND(ROUND(ROUND(G7*F7,4)*100/E7,4)/100,4) -> 1.6776 | K7: =ROUND(ROUND(ROUND(H7*F7,4)*100/E7,4)/100,4) -> 1.6776 | L7: =ROUND(ROUND(ROUND(I7*F7,4)*100/E7,4)/100,4) -> 1.4646 | M7: =(J7-K7)/K55*100 -> 0 | N7: =(J7-L7)/L55*100 -> 0.064723365 | P7: Transport | Q7: =SUM(F50:F51) -> 6.7892 | R7: =SUM(M50:M51) -> 0.43069111 | S7: =SUM(N50:N51) -> 1.5422697
A8: 5 | B8: 01.1.2.01 | C8: Beef with Bone (Average Quality) | D8: 1 Kg | E8: 332.37 | F8: 3.3533 | G8: 1313.73 | H8: 1313.73 | I8: 1164.8 | J8: =ROUND(ROUND(ROUND(G8*F8,4)*100/E8,4)/100,4) -> 13.2543 | K8: =ROUND(ROUND(ROUND(H8*F8,4)*100/E8,4)/100,4) -> 13.2543 | L8: =ROUND(ROUND(ROUND(I8*F8,4)*100/E8,4)/100,4) -> 11.7517 | M8: =(J8-K8)/K55*100 -> 0 | N8: =(J8-L8)/L55*100 -> 0.4565884 | P8: Total | Q8: =SUM(Q4:Q7) -> 100 | R8: =SUM(R4:R7) -> 0.73158872 | S8: =SUM(S4:S7) -> 9.6597344
A9: 6 | B9: 01.1.2.02 | C9: Mutton (Average Quality) | D9: 1 Kg | E9: 657.62 | F9: 2.4387 | G9: 2552.51 | H9: 2552.51 | I9: 2189.16 | J9: =ROUND(ROUND(ROUND(G9*F9,4)*100/E9,4)/100,4) -> 9.4657 | K9: =ROUND(ROUND(ROUND(H9*F9,4)*100/E9,4)/100,4) -> 9.4657 | L9: =ROUND(ROUND(ROUND(I9*F9,4)*100/E9,4)/100,4) -> 8.1182 | M9: =(J9-K9)/K55*100 -> 0 | N9: =(J9-L9)/L55*100 -> 0.40945885
A10: 7 | B10: 01.1.2.03 | C10: Chicken Farm Broiler (Live) | D10: 1 Kg | E10: 141.05 | F10: 3.8681 | G10: 355.43 | H10: 372.51 | I10: 422.13 | J10: =ROUND(ROUND(ROUND(G10*F10,4)*100/E10,4)/100,4) -> 9.7472 | K10: =ROUND(ROUND(ROUND(H10*F10,4)*100/E10,4)/100,4) -> 10.2156 | L10: =ROUND(ROUND(ROUND(I10*F10,4)*100/E10,4)/100,4) -> 11.5763 | M10: =(J10-K10)/K55*100 -> -0.13074252 | N10: =(J10-L10)/L55*100 -> -0.5558005
A11: 8 | B11: 01.1.4.01 | C11: Milk fresh (Un-boiled) | D11: 1 Ltr | E11: 79.31 | F11: 18.3937 | G11: 224.25 | H11: 224.2 | I11: 205.08 | J11: =ROUND(ROUND(ROUND(G11*F11,4)*100/E11,4)/100,4) -> 52.0084 | K11: =ROUND(ROUND(ROUND(H11*F11,4)*100/E11,4)/100,4) -> 51.9968 | L11: =ROUND(ROUND(ROUND(I11*F11,4)*100/E11,4)/100,4) -> 47.5625 | M11: =(J11-K11)/K55*100 -> 0.0032378593 | N11: =(J11-L11)/L55*100 -> 1.3509559
A12: 9 | B12: 01.1.4.03 | C12: Curd (Dahi) Loose | D12: 1 Kg | E12: 97.34 | F12: 1.8181 | G12: 282.06 | H12: 281.99 | I12: 258.8 | J12: =ROUND(ROUND(ROUND(G12*F12,4)*100/E12,4)/100,4) -> 5.2683 | K12: =ROUND(ROUND(ROUND(H12*F12,4)*100/E12,4)/100,4) -> 5.267 | L12: =ROUND(ROUND(ROUND(I12*F12,4)*100/E12,4)/100,4) -> 4.8338 | M12: =(J12-K12)/K55*100 -> 0.00036286354 | N12: =(J12-L12)/L55*100 -> 0.13202959
A13: 10 | B13: 01.1.4.05 | C13: Powdered Milk NIDO 390 gm Polybag | D13: Each | E13: 363.01 | F13: 0.3817 | G13: 1159.43 | H13: 1158.99 | I13: 1086.63 | J13: =ROUND(ROUND(ROUND(G13*F13,4)*100/E13,4)/100,4) -> 1.2191 | K13: =ROUND(ROUND(ROUND(H13*F13,4)*100/E13,4)/100,4) -> 1.2187 | L13: =ROUND(ROUND(ROUND(I13*F13,4)*100/E13,4)/100,4) -> 1.1426 | M13: =(J13-K13)/K55*100 -> 0.00011165032 | N13: =(J13-L13)/L55*100 -> 0.023245716
A14: 11 | B14: 01.1.4.06 | C14: Eggs Hen (Farm) | D14: 1 Dozen | E14: 87.46 | F14: 1.4424 | G14: 259.16 | H14: 242.74 | I14: 283.42 | J14: =ROUND(ROUND(ROUND(G14*F14,4)*100/E14,4)/100,4) -> 4.2741 | K14: =ROUND(ROUND(ROUND(H14*F14,4)*100/E14,4)/100,4) -> 4.0033 | L14: =ROUND(ROUND(ROUND(I14*F14,4)*100/E14,4)/100,4) -> 4.6742 | M14: =(J14-K14)/K55*100 -> 0.075587267 | N14: =(J14-L14)/L55*100 -> -0.12157661
A15: 12 | B15: 01.1.5.02 | C15: Mustard Oil (Average Quality) | D15: 1 Kg | E15: 180.01 | F15: 0.0341 | G15: 564.65 | H15: 563.87 | I15: 544.27 | J15: =ROUND(ROUND(ROUND(G15*F15,4)*100/E15,4)/100,4) -> 0.107 | K15: =ROUND(ROUND(ROUND(H15*F15,4)*100/E15,4)/100,4) -> 0.1068 | L15: =ROUND(ROUND(ROUND(I15*F15,4)*100/E15,4)/100,4) -> 0.1031 | M15: =(J15-K15)/K55*100 -> 5.582516e-05 | N15: =(J15-L15)/L55*100 -> 0.0011850757
A16: 13 | B16: 01.1.5.03 | C16: Cooking Oil DALDA or Other Similar Brand (SN), 5 Litre Tin | D16: Each | E16: 882.81 | F16: 3.126 | G16: 3066.54 | H16: 3065.15 | I16: 2862.82 | J16: =ROUND(ROUND(ROUND(G16*F16,4)*100/E16,4)/100,4) -> 10.8585 | K16: =ROUND(ROUND(ROUND(H16*F16,4)*100/E16,4)/100,4) -> 10.8536 | L16: =ROUND(ROUND(ROUND(I16*F16,4)*100/E16,4)/100,4) -> 10.1371 | M16: =(J16-K16)/K55*100 -> 0.0013677164 | N16: =(J16-L16)/L55*100 -> 0.21920862
A17: 14 | B17: 01.1.5.04 | C17: Vegetable Ghee DALDA/HABIB 2.5 kg Tin | D17: Each | E17: 440.06 | F17: 1.4648 | G17: 1562.4 | H17: 1561.43 | I17: 1460.04 | J17: =ROUND(ROUND(ROUND(G17*F17,4)*100/E17,4)/100,4) -> 5.2007 | K17: =ROUND(ROUND(ROUND(H17*F17,4)*100/E17,4)/100,4) -> 5.1974 | L17: =ROUND(ROUND(ROUND(I17*F17,4)*100/E17,4)/100,4) -> 4.8599 | M17: =(J17-K17)/K55*100 -> 0.00092111514 | N17: =(J17-L17)/L55*100 -> 0.10355738
A18: 15 | B18: 01.1.5.05 | C18: Vegetable Ghee DALDA/HABIB or Other superior Quality 1 kg Pouch | D18: Each | E18: 157.02 | F18: 1.4648 | G18: 610.14 | H18: 609.38 | I18: 568.19 | J18: =ROUND(ROUND(ROUND(G18*F18,4)*100/E18,4)/100,4) -> 5.6918 | K18: =ROUND(ROUND(ROUND(H18*F18,4)*100/E18,4)/100,4) -> 5.6848 | L18: =ROUND(ROUND(ROUND(I18*F18,4)*100/E18,4)/100,4) -> 5.3005 | M18: =(J18-K18)/K55*100 -> 0.0019538806 | N18: =(J18-L18)/L55*100 -> 0.1189026
A19: 16 | B19: 01.1.6.07 | C19: Bananas (Kela) Local | D19: 1 Dozen | E19: 69.39 | F19: 0.9413 | G19: 190.61 | H19: 190.25 | I19: 162.94 | J19: =ROUND(ROUND(ROUND(G19*F19,4)*100/E19,4)/100,4) -> 2.5857 | K19: =ROUND(ROUND(ROUND(H19*F19,4)*100/E19,4)/100,4) -> 2.5808 | L19: =ROUND(ROUND(ROUND(I19*F19,4)*100/E19,4)/100,4) -> 2.2103 | M19: =(J19-K19)/K55*100 -> 0.0013677164 | N19: =(J19-L19)/L55*100 -> 0.11407113
A20: 17 | B20: 01.1.7.01 | C20: Pulse Masoor (Washed) | D20: 1 Kg | E20: 148.73 | F20: 0.4608 | G20: 252.71 | H20: 253.23 | I20: 296.1 | J20: =ROUND(ROUND(ROUND(G20*F20,4)*100/E20,4)/100,4) -> 0.783 | K20: =ROUND(ROUND(ROUND(H20*F20,4)*100/E20,4)/100,4) -> 0.7846 | L20: =ROUND(ROUND(ROUND(I20*F20,4)*100/E20,4)/100,4) -> 0.9174 | M20: =(J20-K20)/K55*100 -> -0.00044660128 | N20: =(J20-L20)/L55*100 -> -0.040839532
A21: 18 | B21: 01.1.7.02 | C21: Pulse Moong (Washed) | D21: 1 Kg | E21: 160.72 | F21: 0.4816 | G21: 361.61 | H21: 362.64 | I21: 387.36 | J21: =ROUND(ROUND(ROUND(G21*F21,4)*100/E21,4)/100,4) -> 1.0836 | K21: =ROUND(ROUND(ROUND(H21*F21,4)*100/E21,4)/100,4) -> 1.0867 | L21: =ROUND(ROUND(ROUND(I21*F21,4)*100/E21,4)/100,4) -> 1.1607 | M21: =(J21-K21)/K55*100 -> -0.00086528998 | N21: =(J21-L21)/L55*100 -> -0.023428035
A22: 19 | B22: 01.1.7.03 | C22: Pulse Mash (Washed) | D22: 1 Kg | E22: 236.58 | F22: 0.3269 | G22: 453.81 | H22: 455.39 | I22: 443.2 | J22: =ROUND(ROUND(ROUND(G22*F22,4)*100/E22,4)/100,4) -> 0.6271 | K22: =ROUND(ROUND(ROUND(H22*F22,4)*100/E22,4)/100,4) -> 0.6292 | L22: =ROUND(ROUND(ROUND(I22*F22,4)*100/E22,4)/100,4) -> 0.6124 | M22: =(J22-K22)/K55*100 -> -0.00058616418 | N22: =(J22-L22)/L55*100 -> 0.0044668238
A23: 20 | B23: 01.1.7.04 | C23: Pulse Gram | D23: 1 Kg | E23: 119.53 | F23: 0.4711 | G23: 243.19 | H23: 242.67 | I23: 304.14 | J23: =ROUND(ROUND(ROUND(G23*F23,4)*100/E23,4)/100,4) -> 0.9585 | K23: =ROUND(ROUND(ROUND(H23*F23,4)*100/E23,4)/100,4) -> 0.9564 | L23: =ROUND(ROUND(ROUND(I23*F23,4)*100/E23,4)/100,4) -> 1.1987 | M23: =(J23-K23)/K55*100 -> 0.00058616418 | N23: =(J23-L23)/L55*100 -> -0.072988509
A24: 21 | B24: 01.1.7.08 | C24: Potatoes | D24: 1 Kg | E24: 24.79 | F24: 1.2157 | G24: 58.04 | H24: 57.4 | I24: 84.25 | J24: =ROUND(ROUND(ROUND(G24*F24,4)*100/E24,4)/100,4) -> 2.8463 | K24: =ROUND(ROUND(ROUND(H24*F24,4)*100/E24,4)/100,4) -> 2.8149 | L24: =ROUND(ROUND(ROUND(I24*F24,4)*100/E24,4)/100,4) -> 4.1316 | M24: =(J24-K24)/K55*100 -> 0.0087645501 | N24: =(J24-L24)/L55*100 -> -0.39055841
A25: 22 | B25: 01.1.7.10 | C25: Onions | D25: 1 Kg | E25: 43.08 | F25: 1.6822 | G25: 102.45 | H25: 107.1 | I25: 55.86 | J25: =ROUND(ROUND(ROUND(G25*F25,4)*100/E25,4)/100,4) -> 4.0005 | K25: =ROUND(ROUND(ROUND(H25*F25,4)*100/E25,4)/100,4) -> 4.1821 | L25: =ROUND(ROUND(ROUND(I25*F25,4)*100/E25,4)/100,4) -> 2.1812 | M25: =(J25-K25)/K55*100 -> -0.050689245 | N25: =(J25-L25)/L55*100 -> 0.55282262
A26: 23 | B26: 01.1.7.11 | C26: Tomatoes | D26: 1 Kg | E26: 46.04 | F26: 0.9816 | G26: 356.88 | H26: 258.9 | I26: 114.09 | J26: =ROUND(ROUND(ROUND(G26*F26,4)*100/E26,4)/100,4) -> 7.6089 | K26: =ROUND(ROUND(ROUND(H26*F26,4)*100/E26,4)/100,4) -> 5.5199 | L26: =ROUND(ROUND(ROUND(I26*F26,4)*100/E26,4)/100,4) -> 2.4325 | M26: =(J26-K26)/K55*100 -> 0.5830938 | N26: =(J26-L26)/L55*100 -> 1.5729297
A27: 24 | B27: 01.1.8.01 | C27: Sugar Refined | D27: 1 Kg | E27: 63.01 | F27: 3.1584 | G27: 149.66 | H27: 149.85 | I27: 181.48 | J27: =ROUND(ROUND(ROUND(G27*F27,4)*100/E27,4)/100,4) -> 7.5018 | K27: =ROUND(ROUND(ROUND(H27*F27,4)*100/E27,4)/100,4) -> 7.5113 | L27: =ROUND(ROUND(ROUND(I27*F27,4)*100/E27,4)/100,4) -> 9.0968 | M27: =(J27-K27)/K55*100 -> -0.0026516951 | N27: =(J27-L27)/L55*100 -> -0.48466558
A28: 25 | B28: 01.1.8.02 | C28: Gur (Average Quality) | D28: 1 Kg | E28: 88.44 | F28: 0.1075 | G28: 242.26 | H28: 242.23 | I28: 249.12 | J28: =ROUND(ROUND(ROUND(G28*F28,4)*100/E28,4)/100,4) -> 0.2945 | K28: =ROUND(ROUND(ROUND(H28*F28,4)*100/E28,4)/100,4) -> 0.2944 | L28: =ROUND(ROUND(ROUND(I28*F28,4)*100/E28,4)/100,4) -> 0.3028 | M28: =(J28-K28)/K55*100 -> 2.791258e-05 | N28: =(J28-L28)/L55*100 -> -0.0025220842
A29: 26 | B29: 01.1.9.06 | C29: Salt Powdered (NATIONAL/SHAN) 800 gm Packet | D29: Each | E29: 24.99 | F29: 0.2279 | G29: 62.14 | H29: 62.14 | I29: 72.77 | J29: =ROUND(ROUND(ROUND(G29*F29,4)*100/E29,4)/100,4) -> 0.5667 | K29: =ROUND(ROUND(ROUND(H29*F29,4)*100/E29,4)/100,4) -> 0.5667 | L29: =ROUND(ROUND(ROUND(I29*F29,4)*100/E29,4)/100,4) -> 0.6636 | M29: =(J29-K29)/K55*100 -> 0 | N29: =(J29-L29)/L55*100 -> -0.029444573
A30: 27 | B30: 01.1.9.07 | C30: Chilies Powder NATIONAL 200 gm Packet | D30: Each | E30: 105 | F30: 0.8454 | G30: 378.9 | H30: 378.9 | I30: 320 | J30: =ROUND(ROUND(ROUND(G30*F30,4)*100/E30,4)/100,4) -> 3.0507 | K30: =ROUND(ROUND(ROUND(H30*F30,4)*100/E30,4)/100,4) -> 3.0507 | L30: =ROUND(ROUND(ROUND(I30*F30,4)*100/E30,4)/100,4) -> 2.5765 | M30: =(J30-K30)/K55*100 -> 0 | N30: =(J30-L30)/L55*100 -> 0.14409305
A31: 28 | B31: 01.1.7.26 | C31: Garlic (Lehsun) | D31: 1 Kg | E31: 203.97 | F31: 0.5795 | G31: 367.05 | H31: 366.66 | I31: 373.34 | J31: =ROUND(ROUND(ROUND(G31*F31,4)*100/E31,4)/100,4) -> 1.0428 | K31: =ROUND(ROUND(ROUND(H31*F31,4)*100/E31,4)/100,4) -> 1.0417 | L31: =ROUND(ROUND(ROUND(I31*F31,4)*100/E31,4)/100,4) -> 1.0607 | M31: =(J31-K31)/K55*100 -> 0.00030703838 | N31: =(J31-L31)/L55*100 -> -0.0054391936
A32: 29 | B32: 01.2.1.01 | C32: Tea Lipton Yellow Label 190 gm Packet | D32: Each | E32: 163.58 | F32: 2.3913 | G32: 460.85 | H32: 458.2 | I32: 447.09 | J32: =ROUND(ROUND(ROUND(G32*F32,4)*100/E32,4)/100,4) -> 6.737 | K32: =ROUND(ROUND(ROUND(H32*F32,4)*100/E32,4)/100,4) -> 6.6982 | L32: =ROUND(ROUND(ROUND(I32*F32,4)*100/E32,4)/100,4) -> 6.5358 | M32: =(J32-K32)/K55*100 -> 0.010830081 | N32: =(J32-L32)/L55*100 -> 0.061137752
A33: 30 | B33: 11.1.1.03 | C33: Cooked Beef at Average Hotel | D33: Per Plate | E33: 78.43 | F33: 1.0497 | G33: 339.36 | H33: 339.16 | I33: 320.92 | J33: =ROUND(ROUND(ROUND(G33*F33,4)*100/E33,4)/100,4) -> 4.542 | K33: =ROUND(ROUND(ROUND(H33*F33,4)*100/E33,4)/100,4) -> 4.5393 | L33: =ROUND(ROUND(ROUND(I33*F33,4)*100/E33,4)/100,4) -> 4.2952 | M33: =(J33-K33)/K55*100 -> 0.00075363966 | N33: =(J33-L33)/L55*100 -> 0.074994021
A34: 31 | B34: 11.1.1.04 | C34: Cooked Daal at Average Hotel | D34: Per Plate | E34: 51.13 | F34: 1.3014 | G34: 182.73 | H34: 182.52 | I34: 178.35 | J34: =ROUND(ROUND(ROUND(G34*F34,4)*100/E34,4)/100,4) -> 4.651 | K34: =ROUND(ROUND(ROUND(H34*F34,4)*100/E34,4)/100,4) -> 4.6456 | L34: =ROUND(ROUND(ROUND(I34*F34,4)*100/E34,4)/100,4) -> 4.5395 | M34: =(J34-K34)/K55*100 -> 0.0015072793 | N34: =(J34-L34)/L55*100 -> 0.03388101
A35: 32 | B35: 11.1.1.06 | C35: Tea Prepared Ordinary | D35: Per Cup | E35: 19.47 | F35: 2.3564 | G35: 68.86 | H35: 68.62 | I35: 63.97 | J35: =ROUND(ROUND(ROUND(G35*F35,4)*100/E35,4)/100,4) -> 8.3339 | K35: =ROUND(ROUND(ROUND(H35*F35,4)*100/E35,4)/100,4) -> 8.3049 | L35: =ROUND(ROUND(ROUND(I35*F35,4)*100/E35,4)/100,4) -> 7.7421 | M35: =(J35-K35)/K55*100 -> 0.0080946482 | N35: =(J35-L35)/L55*100 -> 0.17982764
A36: 33 | B36: 02.2.0.01 | C36: Cigarettes Capstan 20'S Packet | D36: Each | E36: 59.33 | F36: 1.0931 | G36: 256.56 | H36: 256.56 | I36: 243.73 | J36: =ROUND(ROUND(ROUND(G36*F36,4)*100/E36,4)/100,4) -> 4.7269 | K36: =ROUND(ROUND(ROUND(H36*F36,4)*100/E36,4)/100,4) -> 4.7269 | L36: =ROUND(ROUND(ROUND(I36*F36,4)*100/E36,4)/100,4) -> 4.4905 | M36: =(J36-K36)/K55*100 -> 0 | N36: =(J36-L36)/L55*100 -> 0.07183382
A37: 34 | B37: 03.1.1.01 | C37: Long Cloth 57" Gul Ahmed/Al Karam | D37: 1 mtr | E37: 205.42 | F37: 3.9577 | G37: 753.5 | H37: 753.5 | I37: 711.66 | J37: =ROUND(ROUND(ROUND(G37*F37,4)*100/E37,4)/100,4) -> 14.5172 | K37: =ROUND(ROUND(ROUND(H37*F37,4)*100/E37,4)/100,4) -> 14.5172 | L37: =ROUND(ROUND(ROUND(I37*F37,4)*100/E37,4)/100,4) -> 13.7111 | M37: =(J37-K37)/K55*100 -> 0 | N37: =(J37-L37)/L55*100 -> 0.24494603
A38: 35 | B38: 03.1.1.02 | C38: Shirting (Average Quality) | D38: 1 mtr | E38: 154.02 | F38: 0.101 | G38: 579.35 | H38: 579.35 | I38: 543.92 | J38: =ROUND(ROUND(ROUND(G38*F38,4)*100/E38,4)/100,4) -> 0.3799 | K38: =ROUND(ROUND(ROUND(H38*F38,4)*100/E38,4)/100,4) -> 0.3799 | L38: =ROUND(ROUND(ROUND(I38*F38,4)*100/E38,4)/100,4) -> 0.3567 | M38: =(J38-K38)/K55*100 -> 0 | N38: =(J38-L38)/L55*100 -> 0.0070496811
A39: 36 | B39: 03.1.1.04 | C39: Lawn Printed Gul Ahmed/Al Karam | D39: 1 mtr | E39: 273.46 | F39: 2.1473 | G39: 744.33 | H39: 744.33 | I39: 714.74 | J39: =ROUND(ROUND(ROUND(G39*F39,4)*100/E39,4)/100,4) -> 5.8447 | K39: =ROUND(ROUND(ROUND(H39*F39,4)*100/E39,4)/100,4) -> 5.8447 | L39: =ROUND(ROUND(ROUND(I39*F39,4)*100/E39,4)/100,4) -> 5.6124 | M39: =(J39-K39)/K55*100 -> 0 | N39: =(J39-L39)/L55*100 -> 0.070587971
A40: 37 | B40: 03.1.1.05 | C40: Georgette (Average Quality) | D40: 1 mtr | E40: 121.34 | F40: 0.9024 | G40: 363.79 | H40: 363.79 | I40: 323.88 | J40: =ROUND(ROUND(ROUND(G40*F40,4)*100/E40,4)/100,4) -> 2.7055 | K40: =ROUND(ROUND(ROUND(H40*F40,4)*100/E40,4)/100,4) -> 2.7055 | L40: =ROUND(ROUND(ROUND(I40*F40,4)*100/E40,4)/100,4) -> 2.4087 | M40: =(J40-K40)/K55*100 -> 0 | N40: =(J40-L40)/L55*100 -> 0.0901873
...

Sheet Impact Lowest
A1: Statement showing SPI prices, indices, %changes and impacts for 51 items with Base 2015-16 (Lowest)
A2: Current Date = 23/07/2026 ,Previous Date = 16/07/2026 ,Corresponding Date = 24/07/2025
A3: No. | B3: Item Code | C3: Item Description | D3: Unit | E3: Weighted Base Price | F3: Weight | G3: Weighted Prices (Curr) (Prev) (Corr) | J3: Weighted Price Relatives (Curr) (Prev) (Corr) | M3: Impact with Prev Corr | P3: Item group | Q3: Weight | R3: Impact (current with) previous corresponding
A4: 1 | B4: 01.1.1.04 | C4: Wheat Flour Bag | D4: 20 Kg | E4: 779.92 | F4: 6.1372 | G4: 2536.55 | H4: 2551.27 | I4: 1491.87 | J4: =ROUND(ROUND(ROUND(G4*F4,4)*100/E4,4)/100,4) -> 19.9601 | K4: =ROUND(ROUND(ROUND(H4*F4,4)*100/E4,4)/100,4) -> 20.076 | L4: =ROUND(ROUND(ROUND(I4*F4,4)*100/E4,4)/100,4) -> 11.7395 | M4: =(J4-K4)/K55*100 -> -0.033421911 | N4: =(J4-L4)/L55*100 -> 2.5904871 | P4: Food | Q4: =SUM(F4:F36) -> 70.5669 | R4: =SUM(M4:M36) -> 0.77648989 | S4: =SUM(N4:N36) -> 7.0146342
A5: 2 | B5: 01.1.1.10 | C5: Rice Basmati Broken (Average Quality) | D5: 1 Kg | E5: 63.21 | F5: 2.961 | G5: 238.77 | H5: 238.77 | I5: 225.9 | J5: =ROUND(ROUND(ROUND(G5*F5,4)*100/E5,4)/100,4) -> 11.1849 | K5: =ROUND(ROUND(ROUND(H5*F5,4)*100/E5,4)/100,4) -> 11.1849 | L5: =ROUND(ROUND(ROUND(I5*F5,4)*100/E5,4)/100,4) -> 10.582 | M5: =(J5-K5)/K55*100 -> 0 | N5: =(J5-L5)/L55*100 -> 0.1899867 | P5: Non-food | Q5: =SUM(F37:F43,F46:F49,F52,F54) -> 17.4598 | R5: =SUM(M37:M43,M46:M49,M52,M54) -> 2.8836851e-05 | S5: =SUM(N37:N43,N46:N49,N52,N54) -> 1.4159666
A6: 3 | B6: 01.1.1.11 | C6: Rice IRRI-6/9 (Sindh/Punjab) | D6: 1 Kg | E6: 46.47 | F6: 0.5922 | G6: 160.75 | H6: 160.86 | I6: 162.39 | J6: =ROUND(ROUND(ROUND(G6*F6,4)*100/E6,4)/100,4) -> 2.0486 | K6: =ROUND(ROUND(ROUND(H6*F6,4)*100/E6,4)/100,4) -> 2.05 | L6: =ROUND(ROUND(ROUND(I6*F6,4)*100/E6,4)/100,4) -> 2.0695 | M6: =(J6-K6)/K55*100 -> -0.00040371592 | N6: =(J6-L6)/L55*100 -> -0.0065860376 | P6: Utility | Q6: =SUM(F44:F45,F53) -> 10.4946 | R6: =SUM(M44:M45,M53) -> 0 | S6: =SUM(N44:N45,N53) -> 1.4527728
A7: 4 | B7: 01.1.1.12 | C7: Bread plain (Small Size) | D7: Each | E7: 42.71 | F7: 0.1041 | G7: 125.75 | H7: 125.75 | I7: 109.78 | J7: =ROUND(ROUND(ROUND(G7*F7,4)*100/E7,4)/100,4) -> 0.3065 | K7: =ROUND(ROUND(ROUND(H7*F7,4)*100/E7,4)/100,4) -> 0.3065 | L7: =ROUND(ROUND(ROUND(I7*F7,4)*100/E7,4)/100,4) -> 0.2676 | M7: =(J7-K7)/K55*100 -> 0 | N7: =(J7-L7)/L55*100 -> 0.012258223 | P7: Transport | Q7: =SUM(F50:F51) -> 1.4787 | R7: =SUM(M50:M51) -> 0.095997878 | S7: =SUM(N50:N51) -> 0.34742136
A8: 5 | B8: 01.1.2.01 | C8: Beef with Bone (Average Quality) | D8: 1 Kg | E8: 332.37 | F8: 2.4988 | G8: 1313.73 | H8: 1313.73 | I8: 1164.8 | J8: =ROUND(ROUND(ROUND(G8*F8,4)*100/E8,4)/100,4) -> 9.8768 | K8: =ROUND(ROUND(ROUND(H8*F8,4)*100/E8,4)/100,4) -> 9.8768 | L8: =ROUND(ROUND(ROUND(I8*F8,4)*100/E8,4)/100,4) -> 8.7571 | M8: =(J8-K8)/K55*100 -> 0 | N8: =(J8-L8)/L55*100 -> 0.35284145 | P8: Total | Q8: =SUM(Q4:Q7) -> 100 | R8: =SUM(R4:R7) -> 0.87251661 | S8: =SUM(S4:S7) -> 10.230795
A9: 6 | B9: 01.1.2.02 | C9: Mutton (Average Quality) | D9: 1 Kg | E9: 657.62 | F9: 0.5498 | G9: 2552.51 | H9: 2552.51 | I9: 2189.16 | J9: =ROUND(ROUND(ROUND(G9*F9,4)*100/E9,4)/100,4) -> 2.134 | K9: =ROUND(ROUND(ROUND(H9*F9,4)*100/E9,4)/100,4) -> 2.134 | L9: =ROUND(ROUND(ROUND(I9*F9,4)*100/E9,4)/100,4) -> 1.8302 | M9: =(J9-K9)/K55*100 -> 0 | N9: =(J9-L9)/L55*100 -> 0.095733886
A10: 7 | B10: 01.1.2.03 | C10: Chicken Farm Broiler (Live) | D10: 1 Kg | E10: 141.05 | F10: 2.9269 | G10: 355.43 | H10: 372.51 | I10: 422.13 | J10: =ROUND(ROUND(ROUND(G10*F10,4)*100/E10,4)/100,4) -> 7.3755 | K10: =ROUND(ROUND(ROUND(H10*F10,4)*100/E10,4)/100,4) -> 7.7299 | L10: =ROUND(ROUND(ROUND(I10*F10,4)*100/E10,4)/100,4) -> 8.7595 | M10: =(J10-K10)/K55*100 -> -0.1021978 | N10: =(J10-L10)/L55*100 -> -0.43612804
A11: 8 | B11: 01.1.4.01 | C11: Milk fresh (Un-boiled) | D11: 1 Ltr | E11: 79.31 | F11: 17.5449 | G11: 224.25 | H11: 224.2 | I11: 205.08 | J11: =ROUND(ROUND(ROUND(G11*F11,4)*100/E11,4)/100,4) -> 49.6084 | K11: =ROUND(ROUND(ROUND(H11*F11,4)*100/E11,4)/100,4) -> 49.5974 | L11: =ROUND(ROUND(ROUND(I11*F11,4)*100/E11,4)/100,4) -> 45.3676 | M11: =(J11-K11)/K55*100 -> 0.0031720536 | N11: =(J11-L11)/L55*100 -> 1.3363669
A12: 9 | B12: 01.1.4.03 | C12: Curd (Dahi) Loose | D12: 1 Kg | E12: 97.34 | F12: 0.7366 | G12: 282.06 | H12: 281.99 | I12: 258.8 | J12: =ROUND(ROUND(ROUND(G12*F12,4)*100/E12,4)/100,4) -> 2.1344 | K12: =ROUND(ROUND(ROUND(H12*F12,4)*100/E12,4)/100,4) -> 2.1339 | L12: =ROUND(ROUND(ROUND(I12*F12,4)*100/E12,4)/100,4) -> 1.9584 | M12: =(J12-K12)/K55*100 -> 0.00014418426 | N12: =(J12-L12)/L55*100 -> 0.055461369
A13: 10 | B13: 01.1.4.05 | C13: Powdered Milk NIDO 390 gm Polybag | D13: Each | E13: 363.01 | F13: 0.0803 | G13: 1159.43 | H13: 1158.99 | I13: 1086.63 | J13: =ROUND(ROUND(ROUND(G13*F13,4)*100/E13,4)/100,4) -> 0.2565 | K13: =ROUND(ROUND(ROUND(H13*F13,4)*100/E13,4)/100,4) -> 0.2564 | L13: =ROUND(ROUND(ROUND(I13*F13,4)*100/E13,4)/100,4) -> 0.2404 | M13: =(J13-K13)/K55*100 -> 2.8836851e-05 | N13: =(J13-L13)/L55*100 -> 0.0050734548
